Workbook

Sheet Resumen
A1: OFERTA TÉCNICO-ECONÓMICA
A2: Hospital Universitari Vall d'Hebron
A3: Mantenimiento integral de instalaciones · Bloque General + Torre Infantil + Pediatría
A5: Expediente: | B5: HUV-2026-MANT-INT
A6: Duración del contrato: | B6: 24 meses (prorrogables 24 adicionales)
A7: Fecha límite licitación: | B7: 30 de junio de 2026
A8: Presupuesto máximo anual: | B8: 2.850.000,00 €
A9: Superficie: | B9: 180.000 m² en 9 edificios
A11: INSTRUCCIONES AL LICITADOR
A12: Rellene únicamente las columnas en amarillo (precios unitarios). El resto se recalcula automáticamente.
A14: Cap. | B14: Descripción | F14: Subtotal anual (€)
A15: 1 | B15: Climatización (HVAC) | F15: ='1. Climatización'!G52
A16: 2 | B16: Electricidad y BT | F16: ='2. Electricidad'!G42
A17: 3 | B17: Protección contra incendios (PCI) | F17: ='3. PCI'!G32
A18: 4 | B18: Fontanería y ACS | F18: ='4. Fontanería'!G27
A19: 5 | B19: Aparatos elevadores | F19: ='5. Elevadores'!G19
A20: 6 | B20: Equipos especiales y singulares | F20: ='6. Equipos especiales'!G25
A21: 7 | B21: Personal adscrito | F21: ='7. Personal adscrito'!E19
A22: 8 | B22: Mejoras opcionales | F22: ='8. Mejoras opcionales'!F17
A24: TOTAL OFERTA ANUAL (€) | F24: =SUM(F15:F22)
A25: TOTAL OFERTA CONTRATO COMPLETO (24 meses) (€) | F25: =F24*2

Sheet 1. Climatización
A1: CAPÍTULO 1
A2: CLIMATIZACIÓN (HVAC)
A3: Cliente: Hospital Universitari Vall d'Hebron — Expediente: HUV-2026-MANT-INT
A5: Código | B5: Descripción | C5: Unidad | D5: Cantidad anual | E5: Frecuencia | F5: Precio unitario oferta (€) | G5: Total (€) | H5: Observaciones cliente
A6: P-HVAC-001 | B6: Revisión mensual enfriadora agua-aire 500 kW Carrier 30XA | C6: ud | D6: 24 | E6: mensual | G6: =IFERROR(D6*F6,"") | H6: 2 enfriadoras × 12 meses
A7: P-HVAC-002 | B7: Revisión mensual climatizador primario área asistencial | C7: ud | D7: 144 | E7: mensual | G7: =IFERROR(D7*F7,"") | H7: 12 climatizadores × 12 meses
A8: P-HVAC-003 | B8: Limpieza filtros climatizador zona administrativa | C8: ud | D8: 96 | E8: mensual | G8: =IFERROR(D8*F8,"") | H8: 8 equipos × 12 meses
A9: P-HVAC-004 | B9: Limpieza filtros climatizador zona quirúrgica | C9: ud | D9: 144 | E9: mensual | G9: =IFERROR(D9*F9,"") | H9: Frecuencia reforzada zona crítica
A10: P-HVAC-005 | B10: Inspección sistema VRV plantas 1-4 Bloque General | C10: ud | D10: 48 | E10: mensual | G10: =IFERROR(D10*F10,"") | H10: 4 plantas × 12 meses
A11: P-HVAC-006 | B11: Inspección sistema VRV Torre Infantil | C11: ud | D11: 60 | E11: mensual | G11: =IFERROR(D11*F11,"") | H11: 5 plantas × 12 meses
A12: P-HVAC-007 | B12: Revisión bombas circulación agua fría primario | C12: ud | D12: 48 | E12: mensual | G12: =IFERROR(D12*F12,"") | H12: 4 bombas × 12 meses
A13: P-HVAC-008 | B13: Revisión bombas circulación agua caliente secundario | C13: ud | D13: 36 | E13: mensual | G13: =IFERROR(D13*F13,"") | H13: 3 bombas × 12 meses
A14: P-HVAC-009 | B14: Verificación torres de refrigeración — control Legionella | C14: ud | D14: 48 | E14: mensual | G14: =IFERROR(D14*F14,"") | H14: 4 torres × 12 meses
A15: P-HVAC-010 | B15: Ronda diaria centro de control climatización | C15: ronda | D15: 365 | E15: diaria | G15: =IFERROR(D15*F15,"")
A16: P-HVAC-011 | B16: Revisión completa torres refrigeración | C16: ud | D16: 16 | E16: trimestral | G16: =IFERROR(D16*F16,"") | H16: 4 torres × 4 trimestres
A17: P-HVAC-012 | B17: Análisis químico agua circuitos refrigeración | C17: análisis | D17: 20 | E17: trimestral | G17: =IFERROR(D17*F17,"") | H17: 5 circuitos × 4
A18: P-HVAC-013 | B18: Desinfección bandejas condensados | C18: ud | D18: 48 | E18: trimestral | G18: =IFERROR(D18*F18,"")
A19: P-HVAC-014 | B19: Revisión compresores scroll unidades VRV | C19: ud | D19: 32 | E19: trimestral | G19: =IFERROR(D19*F19,"")
A20: P-HVAC-015 | B20: Verificación presiones refrigerante R-410A enfriadoras | C20: ud | D20: 8 | E20: trimestral | G20: =IFERROR(D20*F20,"")
A21: P-HVAC-016 | B21: Limpieza baterías condensación unidades exteriores | C21: ud | D21: 40 | E21: trimestral | G21: =IFERROR(D21*F21,"")
A22: P-HVAC-017 | B22: Revisión conducto aire primario quirófanos | C22: m | D22: 320 | E22: trimestral | G22: =IFERROR(D22*F22,"") | H22: 80 m × 4 trimestres
A23: P-HVAC-018 | B23: Comprobación funcional válvulas 3 vías | C23: ud | D23: 48 | E23: trimestral | G23: =IFERROR(D23*F23,"")
A24: P-HVAC-019 | B24: Revisión variadores frecuencia ventiladores | C24: ud | D24: 24 | E24: trimestral | G24: =IFERROR(D24*F24,"")
A25: P-HVAC-020 | B25: Inspección aislamiento térmico tuberías principales | C25: m | D25: 1200 | E25: trimestral | G25: =IFERROR(D25*F25,"")
A26: P-HVAC-021 | B26: Sustitución filtros climatizadores área limpia | C26: ud | D26: 48 | E26: semestral | G26: =IFERROR(D26*F26,"")
A27: P-HVAC-022 | B27: Sustitución filtros HEPA quirófanos Q1-Q12 | C27: ud | D27: 24 | E27: semestral | G27: =IFERROR(D27*F27,"") | H27: 12 quirófanos × 2
A28: P-HVAC-023 | B28: Sustitución filtros HEPA UCI y REA | C28: ud | D28: 36 | E28: semestral | G28: =IFERROR(D28*F28,"")
A29: P-HVAC-024 | B29: Revisión sensores temperatura/humedad área crítica | C29: ud | D29: 80 | E29: semestral | G29: =IFERROR(D29*F29,"")
A30: P-HVAC-025 | B30: Calibración controladores BMS climatización | C30: ud | D30: 16 | E30: semestral | G30: =IFERROR(D30*F30,"")
A31: P-HVAC-026 | B31: Verificación rendimiento estacional SEER/COP | C31: ud | D31: 4 | E31: semestral | G31: =IFERROR(D31*F31,"")
A32: P-HVAC-027 | B32: Revisión trampas de vapor sistema ACS primario | C32: ud | D32: 48 | E32: semestral | G32: =IFERROR(D32*F32,"")
A33: P-HVAC-028 | B33: Inspección chimeneas y salidas exhaust laboratorio | C33: ud | D33: 12 | E33: semestral | G33: =IFERROR(D33*F33,"")
A34: P-HVAC-029 | B34: Cambio aceite compresores enfriadoras | C34: ud | D34: 2 | E34: anual | G34: =IFERROR(D34*F34,"")
A35: P-HVAC-030 | B35: Revisión anual torres refrigeración — desmontaje | C35: ud | D35: 4 | E35: anual | G35: =IFERROR(D35*F35,"")
A36: P-HVAC-031 | B36: Carga refrigerante R-410A (si es necesario) | C36: kg | D36: 40 | E36: anual | G36: =IFERROR(D36*F36,"") | H36: Bolsa estimada
A37: P-HVAC-032 | B37: Análisis termográfico climatizadores principales | C37: ud | D37: 20 | E37: anual | G37: =IFERROR(D37*F37,"")
A38: P-HVAC-033 | B38: Revisión sellos mecánicos bombas | C38: ud | D38: 7 | E38: anual | G38: =IFERROR(D38*F38,"")
A39: P-HVAC-034 | B39: Ensayo funcional anual sistema críticos | C39: ud | D39: 1 | E39: anual | G39: =IFERROR(D39*F39,"")
A40: P-HVAC-035 | B40: Revisión anual válvulas seguridad | C40: ud | D40: 24 | E40: anual | G40: =IFERROR(D40*F40,"")
A41: P-HVAC-036 | B41: Auditoría anual del plan preventivo HVAC | C41: ud | D41: 1 | E41: anual | G41: =IFERROR(D41*F41,"")
...

Sheet 2. Electricidad
A1: CAPÍTULO 2
A2: ELECTRICIDAD Y BT
A3: Cliente: Hospital Universitari Vall d'Hebron — Expediente: HUV-2026-MANT-INT
A5: Código | B5: Descripción | C5: Unidad | D5: Cantidad anual | E5: Frecuencia | F5: Precio unitario oferta (€) | G5: Total (€) | H5: Observaciones cliente
A6: P-ELE-001 | B6: Revisión mensual cuadro general BT Bloque General | C6: ud | D6: 12 | E6: mensual | G6: =IFERROR(D6*F6,"")
A7: P-ELE-002 | B7: Revisión mensual cuadro general BT Torre Infantil | C7: ud | D7: 12 | E7: mensual | G7: =IFERROR(D7*F7,"")
A8: P-ELE-003 | B8: Revisión mensual cuadro general BT Pediatría | C8: ud | D8: 12 | E8: mensual | G8: =IFERROR(D8*F8,"")
A9: P-ELE-004 | B9: Revisión trimestral cuadros secundarios planta | C9: ud | D9: 64 | E9: trimestral | G9: =IFERROR(D9*F9,"") | H9: 16 cuadros × 4
A10: P-ELE-005 | B10: Revisión trimestral centros de transformación | C10: ud | D10: 8 | E10: trimestral | G10: =IFERROR(D10*F10,"") | H10: 2 CT × 4
A11: P-ELE-006 | B11: Verificación apriete conexiones cuadros principales | C11: ud | D11: 12 | E11: semestral | G11: =IFERROR(D11*F11,"")
A12: P-ELE-007 | B12: Verificación apriete conexiones cuadros secundarios | C12: ud | D12: 32 | E12: semestral | G12: =IFERROR(D12*F12,"")
A13: P-ELE-008 | B13: Análisis calidad onda en puntos críticos | C13: ud | D13: 16 | E13: semestral | G13: =IFERROR(D13*F13,"")
A14: P-ELE-009 | B14: Análisis termográfico anual CT + cuadros generales | C14: ud | D14: 5 | E14: anual | G14: =IFERROR(D14*F14,"")
A15: P-ELE-010 | B15: Análisis termográfico anual cuadros secundarios | C15: ud | D15: 16 | E15: anual | G15: =IFERROR(D15*F15,"")
A16: P-ELE-011 | B16: Ensayos anuales aisladores MT CT | C16: ud | D16: 2 | E16: anual | G16: =IFERROR(D16*F16,"")
A17: P-ELE-012 | B17: Revisión anual puesta a tierra | C17: ud | D17: 3 | E17: anual | G17: =IFERROR(D17*F17,"")
A18: P-ELE-013 | B18: Revisión mensual SAI hospitalario 250 kVA | C18: ud | D18: 12 | E18: mensual | G18: =IFERROR(D18*F18,"") | H18: SAI principal
A19: P-ELE-014 | B19: Revisión mensual SAI quirófano 40 kVA | C19: ud | D19: 72 | E19: mensual | G19: =IFERROR(D19*F19,"") | H19: 6 SAIs × 12 meses
A20: P-ELE-015 | B20: Ensayo funcional SAI con carga (semestral) | C20: ud | D20: 14 | E20: semestral | G20: =IFERROR(D20*F20,"")
A21: P-ELE-016 | B21: Sustitución baterías SAI (quinquenal) | C21: ud | D21: 1 | E21: bolsa anual | G21: =IFERROR(D21*F21,"") | H21: Amortización anual
A22: P-ELE-017 | B22: Revisión mensual grupo electrógeno 1600 kVA | C22: ud | D22: 12 | E22: mensual | G22: =IFERROR(D22*F22,"")
A23: P-ELE-018 | B23: Ensayo semanal en vacío del GE | C23: ud | D23: 52 | E23: semanal | G23: =IFERROR(D23*F23,"")
A24: P-ELE-019 | B24: Ensayo mensual con carga del GE | C24: ud | D24: 12 | E24: mensual | G24: =IFERROR(D24*F24,"")
A25: P-ELE-020 | B25: Cambio aceite y filtros GE (anual) | C25: ud | D25: 1 | E25: anual | G25: =IFERROR(D25*F25,"")
A26: P-ELE-021 | B26: Análisis de gasóleo — calidad combustible | C26: ud | D26: 2 | E26: semestral | G26: =IFERROR(D26*F26,"")
A27: P-ELE-022 | B27: Sustitución programada luminarias LED áreas comunes | C27: ud | D27: 200 | E27: bolsa anual | G27: =IFERROR(D27*F27,"") | H27: Estimación 4% parque
A28: P-ELE-023 | B28: Revisión alumbrado de emergencia (trimestral) | C28: ud | D28: 800 | E28: trimestral | G28: =IFERROR(D28*F28,"") | H28: 200 ud × 4
A29: P-ELE-024 | B29: Ensayo anual alumbrado de emergencia (autonomía) | C29: ud | D29: 200 | E29: anual | G29: =IFERROR(D29*F29,"")
A30: P-ELE-025 | B30: Hora técnico oficial 1ª electricidad — correctivo | C30: h | D30: 600 | E30: bolsa anual | G30: =IFERROR(D30*F30,"")
A31: P-ELE-026 | B31: Hora técnico oficial 2ª electricidad — correctivo | C31: h | D31: 300 | E31: bolsa anual | G31: =IFERROR(D31*F31,"")
A32: P-ELE-027 | B32: Hora electricista guardia localizada 24/7 | C32: h | D32: 200 | E32: bolsa anual | G32: =IFERROR(D32*F32,"")
A33: P-ELE-028 | B33: Diagnóstico averías complejas MT | C33: h | D33: 20 | E33: bolsa anual | G33: =IFERROR(D33*F33,"") | H33: Solo ingeniero certificado MT
A34: P-ELE-029 | B34: Mantenimiento sistema BMS Saia-Burgess | C34: ud | D34: 4 | E34: trimestral | G34: =IFERROR(D34*F34,"") | H34: PLATAFORMA ESPECÍFICA HUVH
A35: P-ELE-030 | B35: Supervisión programación BMS — ajustes menores | C35: h | D35: 40 | E35: bolsa anual | G35: =IFERROR(D35*F35,"")
A36: P-ELE-031 | B36: Mantenimiento red datos infraestructura IT | C36: ud | D36: 4 | E36: trimestral | G36: =IFERROR(D36*F36,"") | H36: FUERA DEL ALCANCE HABITUAL — revisar
A37: P-ELE-032 | B37: Adecuación normativa según RD 842/2002 — incidencias | C37: lote | D37: 1 | E37: anual | G37: =IFERROR(D37*F37,"") | H37: A valorar con incidencia
A38: P-ELE-033 | B38: Gestión residuos eléctricos (RAEE) | C38: kg | D38: 800 | E38: anual | G38: =IFERROR(D38*F38,"")
A39: P-ELE-034 | B39: Mantenimiento sistema seguridad eléctrica quirófano | C39: ud | D39: 48 | E39: mensual | G39: =IFERROR(D39*F39,"") | H39: Normativa específica quirófanos
A40: P-ELE-035 | B40: Mantenimiento equipos singulares eléctricos | C40: lote | D40: 1 | E40: anual | G40: =IFERROR(D40*F40,"") | H40: A valorar con dirección técnica
F42: Subtotal capítulo 2: | G42: =SUM(G6:G40)

Sheet 3. PCI
A1: CAPÍTULO 3
A2: PROTECCIÓN CONTRA INCENDIOS (PCI)
A3: Cliente: Hospital Universitari Vall d'Hebron — Expediente: HUV-2026-MANT-INT
A5: Código | B5: Descripción | C5: Unidad | D5: Cantidad anual | E5: Frecuencia | F5: Precio unitario oferta (€) | G5: Total (€) | H5: Observaciones cliente
A6: P-PCI-001 | B6: Revisión trimestral extintores polvo 6 kg | C6: ud | D6: 1600 | E6: trimestral | G6: =IFERROR(D6*F6,"") | H6: 400 extintores × 4
A7: P-PCI-002 | B7: Revisión trimestral extintores CO2 5 kg | C7: ud | D7: 320 | E7: trimestral | G7: =IFERROR(D7*F7,"") | H7: 80 extintores × 4
A8: P-PCI-003 | B8: Revisión trimestral BIEs 25 mm | C8: ud | D8: 480 | E8: trimestral | G8: =IFERROR(D8*F8,"") | H8: 120 BIEs × 4
A9: P-PCI-004 | B9: Prueba de presión BIEs | C9: ud | D9: 240 | E9: semestral | G9: =IFERROR(D9*F9,"")
A10: P-PCI-005 | B10: Revisión trimestral sistema detección zona asistencial | C10: zona | D10: 160 | E10: trimestral | G10: =IFERROR(D10*F10,"") | H10: 40 zonas × 4
A11: P-PCI-006 | B11: Revisión trimestral sistema detección zona técnica | C11: zona | D11: 80 | E11: trimestral | G11: =IFERROR(D11*F11,"") | H11: 20 zonas × 4
A12: P-PCI-007 | B12: Ensayo funcional detectores humo (muestreo 5%) | C12: ud | D12: 400 | E12: semestral | G12: =IFERROR(D12*F12,"")
A13: P-PCI-008 | B13: Ensayo funcional detectores térmicos | C13: ud | D13: 60 | E13: semestral | G13: =IFERROR(D13*F13,"")
A14: P-PCI-009 | B14: Revisión trimestral central de incendios principal | C14: ud | D14: 4 | E14: trimestral | G14: =IFERROR(D14*F14,"")
A15: P-PCI-010 | B15: Revisión trimestral centrales secundarias | C15: ud | D15: 16 | E15: trimestral | G15: =IFERROR(D15*F15,"")
A16: P-PCI-011 | B16: Revisión pulsadores alarma manual | C16: ud | D16: 200 | E16: anual | G16: =IFERROR(D16*F16,"")
A17: P-PCI-012 | B17: Revisión rociadores (por cabezal) | C17: ud | D17: 4800 | E17: anual | G17: =IFERROR(D17*F17,"") | H17: Muestreo visual + presión
A18: P-PCI-013 | B18: Revisión anual puestos de control rociadores | C18: ud | D18: 12 | E18: anual | G18: =IFERROR(D18*F18,"")
A19: P-PCI-014 | B19: Ensayo anual bomba jockey sistema rociadores | C19: ud | D19: 4 | E19: anual | G19: =IFERROR(D19*F19,"")
A20: P-PCI-015 | B20: Revisión anual sistemas de detección aspirativa laboratorios | C20: ud | D20: 8 | E20: anual | G20: =IFERROR(D20*F20,"")
A21: P-PCI-016 | B21: Revisión trimestral puertas cortafuegos (mecanismo) | C21: ud | D21: 360 | E21: trimestral | G21: =IFERROR(D21*F21,"") | H21: 90 puertas × 4
A22: P-PCI-017 | B22: Revisión anual compuertas sectorización conductos | C22: ud | D22: 120 | E22: anual | G22: =IFERROR(D22*F22,"")
A23: P-PCI-018 | B23: Revisión anual exutorios de humos | C23: ud | D23: 20 | E23: anual | G23: =IFERROR(D23*F23,"")
A24: P-PCI-019 | B24: Revisión trimestral iluminación emergencia sectores PCI | C24: ud | D24: 600 | E24: trimestral | G24: =IFERROR(D24*F24,"") | H24: DUPLICADO con P-ELE-023?
A25: P-PCI-020 | B25: Verificación señalización fotoluminiscente | C25: ud | D25: 800 | E25: semestral | G25: =IFERROR(D25*F25,"")
A26: P-PCI-021 | B26: Mantenimiento anual instalación fija CO2 centro control | C26: ud | D26: 1 | E26: anual | G26: =IFERROR(D26*F26,"") | H26: SISTEMA SINGULAR
A27: P-PCI-022 | B27: Mantenimiento anual instalación fija gas FM-200 CPD | C27: ud | D27: 1 | E27: anual | G27: =IFERROR(D27*F27,"") | H27: SISTEMA SINGULAR
A28: P-PCI-023 | B28: Hora técnico oficial 1ª PCI — correctivo | C28: h | D28: 400 | E28: bolsa anual | G28: =IFERROR(D28*F28,"")
A29: P-PCI-024 | B29: Gestión residuos agentes extintores retirados | C29: kg | D29: 120 | E29: anual | G29: =IFERROR(D29*F29,"")
A30: P-PCI-025 | B30: Auditoría anual plan preventivo PCI | C30: ud | D30: 1 | E30: anual | G30: =IFERROR(D30*F30,"")
F32: Subtotal capítulo 3: | G32: =SUM(G6:G30)

Sheet 4. Fontanería
A1: CAPÍTULO 4
A2: FONTANERÍA Y ACS
A3: Cliente: Hospital Universitari Vall d'Hebron — Expediente: HUV-2026-MANT-INT
A5: Código | B5: Descripción | C5: Unidad | D5: Cantidad anual | E5: Frecuencia | F5: Precio unitario oferta (€) | G5: Total (€) | H5: Observaciones cliente
A6: P-FON-001 | B6: Ronda mensual sala calderas | C6: ud | D6: 12 | E6: mensual | G6: =IFERROR(D6*F6,"")
A7: P-FON-002 | B7: Análisis mensual temperatura ACS (red) | C7: punto | D7: 120 | E7: mensual | G7: =IFERROR(D7*F7,"") | H7: 10 puntos × 12 meses
A8: P-FON-003 | B8: Análisis quincenal temperatura acumuladores ACS | C8: ud | D8: 96 | E8: quincenal | G8: =IFERROR(D8*F8,"") | H8: 4 acumuladores × 24
A9: P-FON-004 | B9: Limpieza y desinfección filtros agua potable | C9: ud | D9: 48 | E9: trimestral | G9: =IFERROR(D9*F9,"")
A10: P-FON-005 | B10: Choque térmico ACS red principal (mensual) | C10: ud | D10: 12 | E10: mensual | G10: =IFERROR(D10*F10,"")
A11: P-FON-006 | B11: Choque térmico ACS red secundaria (trimestral) | C11: ud | D11: 16 | E11: trimestral | G11: =IFERROR(D11*F11,"") | H11: 4 redes × 4
A12: P-FON-007 | B12: Análisis legionelosis laboratorio acreditado | C12: análisis | D12: 48 | E12: trimestral | G12: =IFERROR(D12*F12,"")
A13: P-FON-008 | B13: Análisis químico agua sanitaria | C13: análisis | D13: 12 | E13: trimestral | G13: =IFERROR(D13*F13,"")
A14: P-FON-009 | B14: Revisión grupos presión agua fría | C14: ud | D14: 24 | E14: trimestral | G14: =IFERROR(D14*F14,"") | H14: 6 grupos × 4
A15: P-FON-010 | B15: Revisión calderas condensación gas | C15: ud | D15: 16 | E15: trimestral | G15: =IFERROR(D15*F15,"") | H15: 4 calderas × 4
A16: P-FON-011 | B16: Revisión anual intercambiadores placa ACS | C16: ud | D16: 4 | E16: anual | G16: =IFERROR(D16*F16,"")
A17: P-FON-012 | B17: Revisión anual descalcificadores | C17: ud | D17: 2 | E17: anual | G17: =IFERROR(D17*F17,"")
A18: P-FON-013 | B18: Limpieza y desincrustación serpentines calderas | C18: ud | D18: 4 | E18: anual | G18: =IFERROR(D18*F18,"")
A19: P-FON-014 | B19: Revisión anual tanques ACS | C19: ud | D19: 4 | E19: anual | G19: =IFERROR(D19*F19,"")
A20: P-FON-015 | B20: Ensayo anual válvulas seguridad circuito primario | C20: ud | D20: 12 | E20: anual | G20: =IFERROR(D20*F20,"")
A21: P-FON-016 | B21: Revisión grupos bombeo saneamiento edificios | C21: ud | D21: 8 | E21: trimestral | G21: =IFERROR(D21*F21,"")
A22: P-FON-017 | B22: Limpieza anual arquetas sistemas pluviales | C22: ud | D22: 40 | E22: anual | G22: =IFERROR(D22*F22,"")
A23: P-FON-018 | B23: Mantenimiento planta agua ultrapura laboratorio | C23: ud | D23: 12 | E23: mensual | G23: =IFERROR(D23*F23,"") | H23: SISTEMA SINGULAR LAB
A24: P-FON-019 | B24: Hora técnico oficial 1ª fontanería — correctivo | C24: h | D24: 400 | E24: bolsa anual | G24: =IFERROR(D24*F24,"")
A25: P-FON-020 | B25: Hora fontanero guardia 24/7 | C25: h | D25: 150 | E25: bolsa anual | G25: =IFERROR(D25*F25,"")
F27: Subtotal capítulo 4: | G27: =SUM(G6:G25)

Sheet 5. Elevadores
A1: CAPÍTULO 5
A2: APARATOS ELEVADORES
A3: Cliente: Hospital Universitari Vall d'Hebron — Expediente: HUV-2026-MANT-INT
A5: Código | B5: Descripción | C5: Unidad | D5: Cantidad anual | E5: Frecuencia | F5: Precio unitario oferta (€) | G5: Total (€) | H5: Observaciones cliente
A6: P-ELV-001 | B6: Revisión mensual ascensores asistenciales | C6: ud | D6: 144 | E6: mensual | G6: =IFERROR(D6*F6,"") | H6: 12 ascensores × 12
A7: P-ELV-002 | B7: Revisión mensual ascensores servicio | C7: ud | D7: 96 | E7: mensual | G7: =IFERROR(D7*F7,"") | H7: 8 ascensores × 12
A8: P-ELV-003 | B8: Revisión mensual montacargas | C8: ud | D8: 36 | E8: mensual | G8: =IFERROR(D8*F8,"") | H8: 3 montacargas × 12
A9: P-ELV-004 | B9: Inspección reglamentaria periódica ascensores (bienal) | C9: ud | D9: 10 | E9: bolsa anual | G9: =IFERROR(D9*F9,"") | H9: Amortización 10/año
A10: P-ELV-005 | B10: Sustitución cables tracción (cuando procede) | C10: ud | D10: 2 | E10: bolsa anual | G10: =IFERROR(D10*F10,"") | H10: Según desgaste
A11: P-ELV-006 | B11: Lubricación guías y piezas mecánicas | C11: ud | D11: 23 | E11: trimestral | G11: =IFERROR(D11*F11,"")
A12: P-ELV-007 | B12: Revisión trimestral botoneras y displays | C12: ud | D12: 92 | E12: trimestral | G12: =IFERROR(D12*F12,"")
A13: P-ELV-008 | B13: Comprobación funcional sistema comunicación emergencia | C13: ud | D13: 46 | E13: semestral | G13: =IFERROR(D13*F13,"")
A14: P-ELV-009 | B14: Revisión anual baterías sistema emergencia ascensor | C14: ud | D14: 23 | E14: anual | G14: =IFERROR(D14*F14,"")
A15: P-ELV-010 | B15: Mantenimiento tractores y motores | C15: ud | D15: 23 | E15: anual | G15: =IFERROR(D15*F15,"")
A16: P-ELV-011 | B16: Hora técnico ascensorista — correctivo | C16: h | D16: 400 | E16: bolsa anual | G16: =IFERROR(D16*F16,"")
A17: P-ELV-012 | B17: Hora guardia 24/7 ascensores | C17: h | D17: 200 | E17: bolsa anual | G17: =IFERROR(D17*F17,"")
F19: Subtotal capítulo 5: | G19: =SUM(G6:G17)

Sheet 6. Equipos especiales
A1: CAPÍTULO 6
A2: EQUIPOS ESPECIALES Y SINGULARES
A3: Cliente: Hospital Universitari Vall d'Hebron — Expediente: HUV-2026-MANT-INT
A5: Código | B5: Descripción | C5: Unidad | D5: Cantidad anual | E5: Frecuencia | F5: Precio unitario oferta (€) | G5: Total (€) | H5: Observaciones cliente
A6: P-ESP-001 | B6: Mantenimiento sistema aire comprimido medicinal | C6: ud | D6: 12 | E6: mensual | G6: =IFERROR(D6*F6,"") | H6: SISTEMA SINGULAR
A7: P-ESP-002 | B7: Análisis pureza aire medicinal | C7: análisis | D7: 4 | E7: trimestral | G7: =IFERROR(D7*F7,"") | H7: Normativa RD 1277/2003
A8: P-ESP-003 | B8: Mantenimiento sistema vacío medicinal | C8: ud | D8: 12 | E8: mensual | G8: =IFERROR(D8*F8,"")
A9: P-ESP-004 | B9: Revisión central gases medicinales | C9: ud | D9: 12 | E9: mensual | G9: =IFERROR(D9*F9,"")
A10: P-ESP-005 | B10: Control central CO2 criogénico laboratorio | C10: ud | D10: 12 | E10: mensual | G10: =IFERROR(D10*F10,"") | H10: SISTEMA SINGULAR LAB
A11: P-ESP-006 | B11: Mantenimiento sistema climatización PET-TAC (blindaje) | C11: ud | D11: 4 | E11: trimestral | G11: =IFERROR(D11*F11,"") | H11: DUPLICADO con P-HVAC-043?
A12: P-ESP-007 | B12: Mantenimiento cámaras frigoríficas laboratorio -80°C | C12: ud | D12: 48 | E12: mensual | G12: =IFERROR(D12*F12,"") | H12: 4 cámaras × 12
A13: P-ESP-008 | B13: Mantenimiento cámaras frigoríficas laboratorio -40°C | C13: ud | D13: 24 | E13: mensual | G13: =IFERROR(D13*F13,"")
A14: P-ESP-009 | B14: Mantenimiento cámaras frigoríficas +4°C clínicas | C14: ud | D14: 96 | E14: mensual | G14: =IFERROR(D14*F14,"") | H14: 8 cámaras × 12
A15: P-ESP-010 | B15: Servicio guardia 24/7 alarmas técnicas laboratorio | C15: año | D15: 1 | E15: anual | G15: =IFERROR(D15*F15,"")
A16: P-ESP-011 | B16: Mantenimiento cabinas de flujo laminar | C16: ud | D16: 32 | E16: semestral | G16: =IFERROR(D16*F16,"")
A17: P-ESP-012 | B17: Mantenimiento sala limpia ISO 7 farmacia hospitalaria | C17: ud | D17: 4 | E17: trimestral | G17: =IFERROR(D17*F17,"")
A18: P-ESP-013 | B18: Verificación protocolo ISO 14644 sala limpia | C18: ensayo | D18: 2 | E18: semestral | G18: =IFERROR(D18*F18,"")
A19: P-ESP-014 | B19: Mantenimiento morgue y cámaras anatomía patológica | C19: ud | D19: 12 | E19: mensual | G19: =IFERROR(D19*F19,"") | H19: SISTEMA SINGULAR
A20: P-ESP-015 | B20: Mantenimiento incinerador residuos Grupo III | C20: ud | D20: 4 | E20: trimestral | G20: =IFERROR(D20*F20,"") | H20: SISTEMA SINGULAR
A21: P-ESP-016 | B21: Sistema tubo neumático transporte muestras | C21: ud | D21: 24 | E21: quincenal | G21: =IFERROR(D21*F21,"") | H21: SISTEMA SINGULAR HUVH
A22: P-ESP-017 | B22: Mantenimiento helipuerto azotea — balizaje | C22: ud | D22: 12 | E22: mensual | G22: =IFERROR(D22*F22,"")
A23: P-ESP-018 | B23: Verificación protocolo oxigenación helipuerto | C23: ensayo | D23: 2 | E23: semestral | G23: =IFERROR(D23*F23,"")
F25: Subtotal capítulo 6: | G25: =SUM(G6:G23)

Sheet 7. Personal adscrito
A1: CAPÍTULO 7
A2: PERSONAL ADSCRITO AL CONTRATO
A3: Indicar el coste anual estimado por perfil
A5: Código | B5: Perfil | C5: Dedicación h/mes | D5: Coste hora (€) | E5: Coste anual (€) | F5: Observaciones
A6: P-RRHH-001 | B6: Ingeniero responsable del contrato | C6: 30 | E6: =IFERROR(C6*D6*12,"") | F6: Jornada parcial asignada
A7: P-RRHH-002 | B7: Jefe de equipo | C7: 160 | E7: =IFERROR(C7*D7*12,"") | F7: Dedicación completa
A8: P-RRHH-003 | B8: Técnico oficial 1ª HVAC (1) | C8: 160 | E8: =IFERROR(C8*D8*12,"") | F8: Dedicación completa
A9: P-RRHH-004 | B9: Técnico oficial 1ª HVAC (2) | C9: 160 | E9: =IFERROR(C9*D9*12,"") | F9: Dedicación completa
A10: P-RRHH-005 | B10: Técnico oficial 1ª Electricidad (1) | C10: 160 | E10: =IFERROR(C10*D10*12,"") | F10: Dedicación completa
A11: P-RRHH-006 | B11: Técnico oficial 1ª Electricidad (2) | C11: 160 | E11: =IFERROR(C11*D11*12,"") | F11: Dedicación completa
A12: P-RRHH-007 | B12: Técnico oficial 1ª PCI | C12: 160 | E12: =IFERROR(C12*D12*12,"") | F12: Dedicación completa
A13: P-RRHH-008 | B13: Técnico oficial 2ª Fontanería | C13: 160 | E13: =IFERROR(C13*D13*12,"") | F13: Dedicación completa
A14: P-RRHH-009 | B14: Técnico oficial 2ª apoyo multidisciplinar | C14: 160 | E14: =IFERROR(C14*D14*12,"") | F14: Dedicación completa
A15: P-RRHH-010 | B15: Técnico ascensorista (subcontrata certificada) | C15: 80 | E15: =IFERROR(C15*D15*12,"") | F15: Media jornada
A16: P-RRHH-011 | B16: Guardia 24/7 rotativa | C16: 240 | E16: =IFERROR(C16*D16*12,"") | F16: Pool 3 técnicos
A17: P-RRHH-012 | B17: Administrativo GMAO y reporting | C17: 80 | E17: =IFERROR(C17*D17*12,"") | F17: Media jornada
D19: Subtotal capítulo 7: | E19: =SUM(E6:E17) | F19: Subtotal capítulo 7: | G19: =SUM(E6:E17)

Sheet 8. Mejoras opcionales
A1: CAPÍTULO 8
A2: MEJORAS OPCIONALES (no obligatorias)
A3: Propuestas de mejora. Puede proponerse sin coste o con coste — se valorará.
A5: Código | B5: Descripción mejora | C5: Unidad | D5: Cantidad | E5: Coste (€) | F5: Total (€)
A6: M-OPC-001 | B6: Plataforma GMAO avanzada con acceso cliente | C6: año | D6: 1 | F6: =IFERROR(D6*E6,"")
A7: M-OPC-002 | B7: Termografía anual extendida a todo el parque eléctrico | C7: año | D7: 1 | F7: =IFERROR(D7*E7,"")
A8: M-OPC-003 | B8: Analítica energética trimestral con informe | C8: informe | D8: 4 | F8: =IFERROR(D8*E8,"")
A9: M-OPC-004 | B9: App móvil para comunicación técnica ↔ cliente | C9: año | D9: 1 | F9: =IFERROR(D9*E9,"")
A10: M-OPC-005 | B10: Plan formación interna cliente (4 sesiones/año) | C10: sesión | D10: 4 | F10: =IFERROR(D10*E10,"")
A11: M-OPC-006 | B11: Auditoría energética anual específica ISO 50001 | C11: auditoría | D11: 1 | F11: =IFERROR(D11*E11,"")
A12: M-OPC-007 | B12: Dashboard tiempo real BMS hospital — integración | C12: año | D12: 1 | F12: =IFERROR(D12*E12,"")
A13: M-OPC-008 | B13: Plan de contingencia con Plan B para cada sistema crítico | C13: plan | D13: 1 | F13: =IFERROR(D13*E13,"")
A14: M-OPC-009 | B14: Stock rotatorio repuestos críticos en sitio | C14: año | D14: 1 | F14: =IFERROR(D14*E14,"")
A15: M-OPC-010 | B15: Servicio psicología laboral para equipo de guardia | C15: año | D15: 1 | F15: =IFERROR(D15*E15,"")
E17: Subtotal mejoras: | F17: =SUM(F6:F15)
